function NetworkException(message: string, status: number) {
  this.message = message;
  this.status = status;
  this.name = 'NetworkException';
}

function ServerException(json: Object, status: number) {
  this.message = 'There was a Server Exception';
  this.json = json;
  this.status = status;
  this.name = 'ServerException';
}

function ApplicationException(json: Object, status: number) {
  this.message = 'There was an Application Exception';
  this.json = json;
  this.status = status;
  this.name = 'ApplicationException';
}

function InvalidJSONException(body: string, status: number) {
  this.message = 'There was an Invalid JSON Exception';
  this.body = body;
  this.status = status;
  this.name = 'InvalidJSONException';
}

export const parseAPIResponse = (response: Response): Object =>
  new Promise((resolve) => resolve(response.text()))
    .catch((err) => {
      throw new NetworkException(err.message, response.status);
    })
    .then((responseBody: string) => {
      let parsedJSON: Object = null;
      try {
        parsedJSON = responseBody === '' ? null : JSON.parse(responseBody);
      } catch (e) {
        // We should never get these unless response is mangled
        // Or API is not properly implemented
        throw new InvalidJSONException(responseBody, response.status);
      }
      if (response.ok) return parsedJSON;
      if (response.status >= 500) {
        throw new ServerException(parsedJSON, response.status);
      } else {
        throw new ApplicationException(parsedJSON, response.status);
      }
    });

export default parseAPIResponse;
